Workbook
Name Print_Area: EMBALADO!$A$1:$P$94
Name Print_Area: 'VOLCADO '!$A$1:$H$486

Sheet VOLCADO 
A1: CODIGO | B1: TURNO | C1: FECHA | D1: FECHA DE COSECHA | E1: DESTINO | F1: UP | G1: COLOR | H1: CANTIDAD | I1: Produtor | J1: Finca | L1: kg | Q1: Yaquilo
A2: 1-5V | B2: 1 | C2: 46106 | D2: 46097 | E2: NO UE | F2: 0290-003 | G2: A | H2: 29 | I2: Agricola Mares SA | J2: Claudia | P2: 53-3V | Q2: El Trece | R2: Yaquilo | S2: 1 | T2: A | U2: UE
A3: 1-2V | B3: 1 | C3: 46106 | D3: 46097 | E3: NO UE | F3: 0290-003 | G3: A | H3: 40 | I3: Agricola Mares SA | J3: Claudia | P3: 53-5VO | Q3: El 20 | R3: El Trece | S3: 2 | T3: PC | U3: USA
A4: 1-7V | B4: 1 | C4: 46106 | D4: 46097 | E4: NO UE | F4: 0290-003 | G4: A | H4: 20 | I4: Agricola Mares SA | J4: Claudia | P4: 54-11P | Q4: El Tata | R4: El 20 | T4: PC | U4: NO UE
A5: 1-1V | B5: 1 | C5: 46106 | D5: 46097 | E5: NO UE | F5: 0290-003 | G5: A | H5: 30 | I5: Agricola Mares SA | J5: Claudia | P5: 56-7VO | Q5: Limonares | R5: El Tata | T5: VC
A6: 3-2V | B6: 1 | C6: 46106 | D6: 46098 | E6: NO UE | F6: 0290-003 | G6: A | H6: 5 | I6: Agricola Mares SA | J6: Claudia | P6: 59-1VC | Q6: Los Chicos | R6: Limonares | T6: V
A7: 1-9P | B7: 1 | C7: 46106 | D7: 46097 | E7: NO UE | F7: 0290-003 | G7: A | H7: 10 | I7: Agricola Mares SA | J7: Claudia | P7: 59-2V | Q7: Antamapu | R7: Los Chicos | T7: VO
A8: 1-3P | B8: 1 | C8: 46106 | D8: 46097 | E8: NO UE | F8: 0290-003 | G8: A | H8: 29 | I8: Agricola Mares SA | J8: Claudia | P8: 59-3VO | Q8: Claudia | R8: Antamapu | V8: Agricola Mares
A9: 1-4V | B9: 1 | C9: 46107 | D9: 46097 | E9: NO UE | F9: 0290-003 | G9: A | H9: 34 | I9: Agricola Mares SA | J9: Claudia | P9: 60-2V | Q9: Avellaneda | R9: Claudia | V9: Fruit Crop
A10: 3-3V | B10: 1 | C10: 46107 | D10: 46098 | E10: NO UE | F10: 0290-003 | G10: A | H10: 30 | I10: Agricola Mares SA | J10: Claudia | P10: 60-3V | Q10: Maria del Rosario | R10: Avellaneda | V10: Greyco
A11: 3-1P | B11: 1 | C11: 46107 | D11: 46098 | E11: NO UE | F11: 0290-003 | G11: A | H11: 17 | I11: Agricola Mares SA | J11: Claudia | P11: 60-4VO | Q11: Monte Grande | R11: Maria del Rosario | V11: Greenpack
A12: 3-12V | B12: 1 | C12: 46107 | D12: 46098 | E12: NO UE | F12: 0290-003 | G12: A | H12: 12 | I12: Agricola Mares SA | J12: Claudia | P12: 60-5V | Q12: Tajamar | R12: Monte Grande
A13: 3-6VC | B13: 1 | C13: 46107 | D13: 46098 | E13: NO UE | F13: 0290-003 | G13: A | H13: 30 | I13: Agricola Mares SA | J13: Claudia | P13: 60-6VO | Q13: El Molino | R13: Tajamar
A14: 1-6VO | B14: 1 | C14: 46107 | D14: 46097 | E14: NO UE | F14: 0290-003 | G14: A | H14: 32 | I14: Agricola Mares SA | J14: Claudia | P14: 60-7VC | Q14: La Luz | R14: El Molino
A15: 3-10V | B15: 1 | C15: 46107 | D15: 46098 | E15: NO UE | F15: 0290-003 | G15: A | H15: 25 | I15: Agricola Mares SA | J15: Claudia | P15: 60-8V | Q15: El Molino | R15: La Luz
A16: 3-9P | B16: 1 | C16: 46107 | D16: 46098 | E16: NO UE | F16: 0290-003 | G16: A | H16: 4 | I16: Agricola Mares SA | J16: Claudia | P16: 61-1VC | Q16: La Luz
A17: 3-13VO | B17: 1 | C17: 46107 | D17: 46098 | E17: NO UE | F17: 0290-003 | G17: A | H17: 13 | I17: Agricola Mares SA | J17: Claudia | P17: 61-2V
A18: 3-7V | B18: 1 | C18: 46107 | D18: 46098 | E18: NO UE | F18: 0290-003 | G18: A | H18: 30 | I18: Agricola Mares SA | J18: Claudia | P18: 61-3V
A19: 3-11V | B19: 1 | C19: 46107 | D19: 46098 | E19: NO UE | F19: 0290-003 | G19: A | H19: 7 | I19: Agricola Mares SA | J19: Claudia | P19: 61-4VO
A20: 3-5V | B20: 1 | C20: 46107 | D20: 46098 | E20: NO UE | F20: 0290-003 | G20: A | H20: 30 | I20: Agricola Mares SA | J20: Claudia | P20: 61-5V
A21: 3-4V | B21: 1 | C21: 46108 | D21: 46098 | E21: NO UE | F21: 0290-003 | G21: A | H21: 33 | I21: Agricola Mares SA | J21: Claudia | P21: 61-6VO
A22: 3-8VO | B22: 1 | C22: 46108 | D22: 46098 | E22: NO UE | F22: 0290-003 | G22: A | H22: 31 | I22: Agricola Mares SA | J22: Claudia | P22: 62-7VO
A23: 4-7VO | B23: 1 | C23: 46108 | D23: 46098 | E23: NO UE | F23: 0419-006 | G23: A | H23: 15 | I23: Greyco SRL | J23: El Molino | P23: 62-9VC
A24: 4-5VC | B24: 1 | C24: 46108 | D24: 46098 | E24: NO UE | F24: 0419-006 | G24: A | H24: 15 | I24: Greyco SRL | J24: El Molino | P24: 62-10V
A25: 4-1P | B25: 1 | C25: 46108 | D25: 46098 | E25: NO UE | F25: 0419-006 | G25: A | H25: 3 | I25: Greyco SRL | J25: El Molino | P25: 62-11VO
A26: 4-2VC | B26: 1 | C26: 46108 | D26: 46098 | E26: NO UE | F26: 0419-006 | G26: A | H26: 15 | I26: Greyco SRL | J26: El Molino | P26: 62-12VC
A27: 4-6V | B27: 1 | C27: 46108 | D27: 46098 | E27: NO UE | F27: 0419-006 | G27: A | H27: 10 | I27: Greyco SRL | J27: El Molino | P27: 63-1P
A28: 4-3V | B28: 1 | C28: 46108 | D28: 46098 | E28: NO UE | F28: 0419-006 | G28: A | H28: 21 | I28: Greyco SRL | J28: El Molino | P28: 63-2VC
... A35: 5-2VC | B35: 1 | C35: 46108 | D35: 46098 | E35: NO UE | F35: 0136-001 | G35: A | H35: 24 | I35: Vision Empresarial del noroeste S.R.L | J35: Antamapu | P35: 64-5V
A36: 5-3V | B36: 1 | C36: 46108 | D36: 46098 | E36: NO UE | F36: 0136-001 | G36: A | H36: 9 | I36: Vision Empresarial del noroeste S.R.L | J36: Antamapu | O36: =129*370 -> 47730 | P36: 64-6V
A37: 8-4P | B37: 1 | C37: 46108 | D37: 46101 | E37: NO UE | F37: 0136-001 | G37: A | H37: 8 | I37: Vision Empresarial del noroeste S.R.L | J37: Antamapu | P37: 64-7V
A38: 2-5V | B38: 1 | C38: 46108 | D38: 46097 | E38: NO UE | F38: 0136-001 | G38: A | H38: 11 | I38: Vision Empresarial del noroeste S.R.L | J38: Antamapu | P38: 64-8VO
A39: 8-1VC | B39: 1 | C39: 46108 | D39: 46101 | E39: NO UE | F39: 0136-001 | G39: A | H39: 27 | I39: Vision Empresarial del noroeste S.R.L | J39: Antamapu | P39: 64-9V
A40: 8-2V | B40: 1 | C40: 46108 | D40: 46101 | E40: NO UE | F40: 0290-003 | G40: A | H40: 30 | I40: Agricola Mares SA | J40: Claudia | P40: 65-1VC
A41: 6-10V | B41: 1 | C41: 46108 | D41: 46101 | E41: NO UE | F41: 0290-003 | G41: A | H41: 30 | I41: Agricola Mares SA | J41: Claudia | P41: 65-2V
A42: 6-12VC | B42: 1 | C42: 46108 | D42: 46101 | E42: NO UE | F42: 0290-003 | G42: A | H42: 12 | I42: Agricola Mares SA | J42: Claudia | P42: 65-3V
A43: 7-1VC | B43: 1 | C43: 46108 | D43: 46101 | E43: NO UE | F43: 0290-003 | G43: A | H43: 17 | I43: Agricola Mares SA | J43: Claudia | P43: 65-4VO
A44: 6-5V | B44: 1 | C44: 46108 | D44: 46101 | E44: NO UE | F44: 0290-003 | G44: A | H44: 30 | I44: Agricola Mares SA | J44: Claudia | P44: 66-4V
A45: 1-8VO | B45: 1 | C45: 46109 | D45: 46097 | E45: NO UE | F45: 0290-003 | G45: A | H45: 15 | I45: Agricola Mares SA | J45: Claudia | P45: 67-2VC
A46: 10-4V | B46: 1 | C46: 46109 | D46: 46102 | E46: NO UE | F46: 0290-003 | G46: A | H46: 9 | I46: Agricola Mares SA | J46: Claudia | P46: 67-4V
...

Sheet EMBALADO
A1: Fecha | B1: TURNO | C1: Nombre | D1: Apellido | E1: 1 | F1: 2 | G1: 3 | H1: 4 | I1: 5 | J1: 6 | K1: 7 | L1: 8 | M1: 9 | N1: 10 | O1: 11 | P1: 12 | Q1: Total | R1: Personal
A2: 46106 | B2: 1 | C2: Javier | D2: Alderetes | G2: 11 | H2: 8 | I2: 11 | J2: 25 | K2: 20 | L2: 32 | Q2: =SUM(E2:P2) -> 107 | R2: Greenpack | T2: Greenpack | V2: Contratista | W2: 1
A3: 46106 | B3: 1 | C3: Nadia | D3: Lucena | G3: 16 | H3: 10 | I3: 11 | J3: 15 | K3: 18 | L3: 24 | Q3: =SUM(E3:P3) -> 94 | R3: Greenpack | W3: 2
A4: 46106 | B4: 1 | C4: Alexis | D4: Ceron | G4: 17 | H4: 13 | I4: 13 | J4: 15 | K4: 18 | L4: 24 | Q4: =SUM(E4:P4) -> 100 | R4: Greenpack
A5: 46106 | B5: 1 | C5: Silvia | D5: Caceres | G5: 15 | H5: 9 | I5: 9 | J5: 17 | K5: 15 | L5: 23 | Q5: =SUM(E5:P5) -> 88 | R5: Greenpack
A6: 46106 | B6: 1 | C6: Marcela | D6: Cortes | G6: 15 | H6: 6 | I6: 7 | J6: 14 | K6: 13 | L6: 19 | Q6: =SUM(E6:P6) -> 74 | R6: Greenpack
A7: 46106 | B7: 1 | C7: Gabriela | D7: Espeche | G7: 14 | H7: 7 | I7: 11 | J7: 25 | K7: 24 | L7: 32 | Q7: =SUM(E7:P7) -> 113 | R7: Greenpack
A8: 46106 | B8: 1 | C8: Nahuel | D8: Gonzalez | G8: 11 | H8: 10 | I8: 13 | J8: 19 | K8: 16 | L8: 24 | Q8: =SUM(E8:P8) -> 93 | R8: Greenpack
A9: 46106 | B9: 1 | C9: Braian | D9: Jaimes | G9: 13 | H9: 11 | I9: 9 | J9: 18 | K9: 18 | L9: 24 | Q9: =SUM(E9:P9) -> 93 | R9: Greenpack
A10: 46106 | B10: 1 | C10: Juan | D10: Salazar | G10: 12 | H10: 11 | I10: 12 | J10: 17 | K10: 18 | L10: 24 | Q10: =SUM(E10:P10) -> 94 | R10: Greenpack
A11: 46106 | B11: 1 | C11: Mauricio | D11: Vera | G11: 16 | H11: 10 | I11: 10 | J11: 20 | K11: 21 | L11: 25 | Q11: =SUM(E11:P11) -> 102 | R11: Greenpack
A12: 46106 | B12: 1 | C12: Gonzalo | D12: Sosa | G12: 18 | H12: 13 | I12: 12 | J12: 18 | K12: 22 | L12: 28 | Q12: =SUM(E12:P12) -> 111 | R12: Greenpack
A13: 46106 | B13: 1 | C13: Felix | D13: Atienzo | G13: 9 | H13: 5 | I13: 8 | J13: 14 | K13: 15 | L13: 21 | Q13: =SUM(E13:P13) -> 72 | R13: Greenpack
A14: 46106 | B14: 1 | C14: Federico | D14: Gonzalez | G14: 10 | H14: 9 | I14: 7 | J14: 15 | K14: 15 | L14: 19 | Q14: =SUM(E14:P14) -> 75 | R14: Greenpack
Q15: =SUM(E15:P15) -> 0
A16: 46106 | B16: 1 | C16: Nancy | D16: Mamana | G16: 15 | H16: 8 | I16: 8 | J16: 16 | K16: 9 | L16: 12 | Q16: =SUM(E16:P16) -> 68 | R16: Contratista
A17: 46106 | B17: 1 | C17: Gladis | D17: Dominguez | G17: 14 | H17: 11 | I17: 12 | J17: 19 | K17: 12 | L17: 17 | Q17: =SUM(E17:P17) -> 85 | R17: Contratista
A18: 46106 | B18: 1 | C18: Franco | D18: Ortiz | G18: 13 | H18: 8 | I18: 10 | J18: 13 | K18: 12 | L18: 19 | Q18: =SUM(E18:P18) -> 75 | R18: Contratista
A19: 46106 | B19: 1 | C19: Rafael | D19: Murru | G19: 14 | H19: 10 | I19: 11 | J19: 18 | K19: 18 | L19: 24 | Q19: =SUM(E19:P19) -> 95 | R19: Contratista
A20: 46106 | B20: 1 | C20: Claudio | D20: Cancino | G20: 12 | H20: 8 | I20: 7 | J20: 13 | K20: 14 | L20: 16 | Q20: =SUM(E20:P20) -> 70 | R20: Contratista
A21: 46106 | B21: 1 | C21: Rosalia | D21: Mendoza | G21: 14 | H21: 8 | I21: 9 | J21: 13 | K21: 9 | L21: 14 | Q21: =SUM(E21:P21) -> 67 | R21: Contratista
A22: 46106 | B22: 1 | C22: Willian | D22: Ibañez | G22: 14 | H22: 11 | I22: 10 | J22: 19 | K22: 16 | L22: 26 | Q22: =SUM(E22:P22) -> 96 | R22: Contratista
A23: 46106 | B23: 1 | C23: Claudia | D23: Portales | G23: 14 | H23: 9 | I23: 9 | J23: 16 | K23: 11 | L23: 18 | Q23: =SUM(E23:P23) -> 77 | R23: Contratista
A24: 46107 | B24: 1 | C24: Javier | D24: Alderetes | E24: 15 | F24: 31 | G24: 31 | H24: 29 | I24: 19 | J24: 28 | K24: 31 | L24: 23 | Q24: =SUM(E24:P24) -> 207 | R24: Greenpack
A25: 46107 | B25: 1 | C25: Nadia | D25: Lucena | E25: 12 | F25: 33 | G25: 27 | H25: 22 | I25: 15 | J25: 23 | K25: 25 | L25: 13 | Q25: =SUM(E25:P25) -> 170 | R25: Greenpack
A26: 46107 | B26: 1 | C26: Alexis | D26: Ceron | E26: 13 | F26: 24 | G26: 24 | H26: 24 | I26: 19 | J26: 22 | K26: 22 | L26: 20 | Q26: =SUM(E26:P26) -> 168 | R26: Greenpack
A27: 46107 | B27: 1 | C27: Marcela | D27: Cortes | E27: 11 | F27: 25 | G27: 22 | H27: 23 | I27: 16 | J27: 17 | K27: 19 | L27: 21 | Q27: =SUM(E27:P27) -> 154 | R27: Greenpack
A28: 46107 | B28: 1 | C28: Gabriela | D28: Espeche | E28: 16 | F28: 32 | G28: 18 | H28: 4 | I28: 20 | J28: 26 | K28: 34 | L28: 23 | Q28: =SUM(E28:P28) -> 173 | R28: Greenpack
A29: 46107 | B29: 1 | C29: Nahuel | D29: Gonzalez | E29: 9 | F29: 19 | G29: 23 | H29: 22 | I29: 17 | J29: 23 | K29: 17 | L29: 20 | Q29: =SUM(E29:P29) -> 150 | R29: Greenpack
A30: 46107 | B30: 1 | C30: Braian | D30: Jaimes | E30: 9 | F30: 23 | G30: 27 | H30: 25 | I30: 19 | J30: 28 | K30: 31 | L30: 22 | Q30: =SUM(E30:P30) -> 184 | R30: Greenpack
A31: 46107 | B31: 1 | C31: Juan | D31: Salazar | E31: 10 | F31: 29 | G31: 20 | H31: 21 | I31: 14 | J31: 19 | K31: 21 | L31: 16 | Q31: =SUM(E31:P31) -> 150 | R31: Greenpack
A32: 46107 | B32: 1 | C32: Mauricio | D32: Vera | E32: 13 | F32: 32 | G32: 29 | H32: 25 | I32: 15 | J32: 23 | K32: 23 | L32: 16 | Q32: =SUM(E32:P32) -> 176 | R32: Greenpack
A33: 46107 | B33: 1 | C33: Gonzalo | D33: Sosa | E33: 15 | F33: 35 | G33: 31 | H33: 25 | I33: 18 | J33: 26 | K33: 32 | L33: 24 | Q33: =SUM(E33:P33) -> 206 | R33: Greenpack
A34: 46107 | B34: 1 | C34: Federico | D34: Gonzalez | E34: 8 | F34: 20 | G34: 17 | H34: 15 | I34: 11 | J34: 13 | K34: 17 | L34: 14 | Q34: =SUM(E34:P34) -> 115 | R34: Greenpack
A35: 46107 | B35: 1 | C35: Silvia | D35: Caceres | E35: 12 | F35: 26 | G35: 25 | H35: 25 | I35: 12 | J35: 25 | K35: 25 | L35: 26 | Q35: =SUM(E35:P35) -> 176 | R35: Greenpack
... A37: 46107 | B37: 1 | C37: Jorgelina | D37: Bazan | E37: 4 | F37: 12 | G37: 14 | H37: 16 | I37: 13 | J37: 15 | K37: 19 | L37: 14 | Q37: =SUM(E37:P37) -> 107 | R37: Contratista
A38: 46107 | B38: 1 | C38: Exequiel | D38: Duran | Q38: =SUM(E38:P38) -> 0 | R38: Contratista
A39: 46107 | B39: 1 | C39: Franco | D39: Ortiz | E39: 10 | F39: 23 | G39: 20 | H39: 20 | I39: 17 | J39: 19 | K39: 22 | L39: 19 | Q39: =SUM(E39:P39) -> 150 | R39: Contratista
A40: 46107 | B40: 1 | C40: Rafael | D40: Murru | E40: 7 | F40: 23 | G40: 23 | H40: 19 | I40: 18 | J40: 19 | K40: 25 | L40: 19 | Q40: =SUM(E40:P40) -> 153 | R40: Contratista
A41: 46107 | B41: 1 | C41: Claudio | D41: Cancino | E41: 10 | F41: 21 | G41: 21 | H41: 20 | I41: 17 | J41: 18 | K41: 23 | L41: 20 | Q41: =SUM(E41:P41) -> 150 | R41: Contratista
...

Sheet Hoja1
B1: Nombre | C1: Apellido | D1: 1 | E1: 2 | F1: 3 | G1: 4 | H1: 5 | I1: 6 | J1: 7 | K1: 8 | L1: 9 | M1: 10 | N1: 11 | O1: 12 | P1: Total
B2: Alexis | C2: Ceron | P2: =SUM(D2:O2) -> 0
B3: Braian | C3: Jaimes | P3: =SUM(D3:O3) -> 0
B4: Federico | C4: Gonzalez | P4: =SUM(D4:O4) -> 0
B5: Felix | C5: Atienzo | P5: =SUM(D5:O5) -> 0
B6: Gabriela | C6: Espeche | P6: =SUM(D6:O6) -> 0
B7: Gonzalo | C7: Sosa | P7: =SUM(D7:O7) -> 0
B8: Javier | C8: Alderetes | P8: =SUM(D8:O8) -> 0
B9: Juan | C9: Salazar | P9: =SUM(D9:O9) -> 0
B10: Marcela | C10: Cortes | P10: =SUM(D10:O10) -> 0
B11: Mauricio | C11: Vera | P11: =SUM(D11:O11) -> 0
B12: Nadia | C12: Lucena | P12: =SUM(D12:O12) -> 0
B13: Nahuel | C13: Gonzalez | P13: =SUM(D13:O13) -> 0
B14: Silvia | C14: Caceres | P14: =SUM(D14:O14) -> 0
P15: =SUM(D15:O15) -> 0
P16: =SUM(D16:O16) -> 0
P17: =SUM(D17:O17) -> 0
P18: =SUM(D18:O18) -> 0
P19: =SUM(D19:O19) -> 0
P20: =SUM(D20:O20) -> 0
P21: =SUM(D21:O21) -> 0
P22: =SUM(D22:O22) -> 0
P23: =SUM(D23:O23) -> 0
P24: =SUM(D24:O24) -> 0
P25: =SUM(D25:O25) -> 0
P26: =SUM(D26:O26) -> 0
... P30: =SUM(D30:O30) -> 0

Sheet Planilla
A1: CODIGO | B1: FECHA DE PARTE | C1: FECHA DE COSECHA | D1: CAMARA | E1: FILA | F1: DESTINO | G1: UP | H1: COLOR | I1: CANTIDAD | J1: visual

Sheet RESUMEN
A1: FECHA | B1: 46151 | C1: Pallet * 63 | D1: Pallet *72 | E1: Platto | F1: Pallet *70 | G1: Pallet * 80 | H1: CAJAS 18 KG | I1: CAJAS 15 KG | J1: Confeccion | K1: Cajas | L1: KG | M1: Kg Comercial | N1: Rendimiento Empaque | O1: Rendimiento Comercial %
A2: TURNO | B2: 2 | F2: Piso inicial 15 kg | H2: 0 | J2: 15 kg | K2: =+(F7*70)+(G7*80) -> 0 | L2: =+K2*16 -> 0 | M2: =+K2*15 -> 0
A3: PISO INICIAL | F3: Piso inicial 18 kg | H3: 0 | J3: 18 kg | K3: =+(C7*63)+(D7*72)+(I6+H6)-H3 -> 5000 | L3: =+K3*19 -> 95000 | M3: =+K3*18 -> 90000
A4: PALLET EMBALADORA | C4: 30 | D4: 6 | H4: =(C4*63)+(D4*72)+(F4*70)+(G4*80) -> 2322 | J4: 6 kg | K4: =+E7 -> 0 | L4: =+K4*6.4 -> 0 | M4: =+K4*6 -> 0
A5: PALLET CAJONERA | C5: 29 | D5: 11 | G5: 8 | H5: =+(C5*63)+(D5*72)+(F5*70)+(G5*80) -> 3259 | I5: PISO Embaladora | L5: =+L4+L3+L2 -> 95000 | M5: =SUM(M2:M4) -> 90000 | N5: =+(L5/I12)*100 -> 75.075075 | O5: =+(M5/I12)*100 -> 71.123755
A6: PISO FINAL | F6: Piso Cajonera | H6: 59 | J6: Remontado Embaladora | M6: Rendiento bins | N6: =+((H12-(H13*1.085))/H12)*100 -> 76.523392
A7: TOTALES | C7: =SUM(C2:C6) -> 59 | D7: =SUM(D2:D6) -> 17 | E7: =+E6+E5 -> 0 | F7: =SUM(F2:F6) -> 0 | H7: =+H5+H4+H6 -> 5640 | K7: Rendientos por productor
F8: Pallet total | G8: 84 | K8: Productor | L8: Kg Volcado | M8: Kg Producido | N8: Pisos | O8: Rendimiento comercial
A9: EMBALADORA | H9: =+H4+I6 -> 2322 | K9: Greyco | L9: =+SUMIFS('Produccion por productor'!J:J,'Produccion por productor'!A:A,RESUMEN!$B$1,'Produccion por productor'!B:B,RESUMEN!$B$2,'Produccion por productor'!C:C,RESUMEN!K9) -> 25160 | M9: =+SUMIFS('Produccion por productor'!H:H,'Produccion por productor'!A:A,RESUMEN!$B$1,'Produccion por productor'!B:B,RESUMEN!$B$2,'Produccion por productor'!C:C,RESUMEN!K9) -> 12568.5 | N9: =+SUMIFS('Produccion por productor'!L:L,'Produccion por productor'!A:A,RESUMEN!$B$1,'Produccion por productor'!B:B,RESUMEN!$B$2,'Produccion por productor'!C:C,RESUMEN!K9)-(SUMIFS('Produccion por productor'!K:K,'Produccion por productor'!A:A,RESUMEN!$B$1,'Produccion por productor'!B:B,RESUMEN!$B$2,'Produccion por productor'!C:C,RESUMEN!K9)) -> 360 | O9: =+((M9+N9)/L9)*100 -> 51.385135
A10: FICHAS CONTADAS | H10: =+SUMIFS(EMBALADO!Q:Q,EMBALADO!A:A,RESUMEN!B1,EMBALADO!B:B,RESUMEN!B2) -> 3272 | K10: Greenpack | L10: =+SUMIFS('Produccion por productor'!J:J,'Produccion por productor'!A:A,RESUMEN!$B$1,'Produccion por productor'!B:B,RESUMEN!$B$2,'Produccion por productor'!C:C,RESUMEN!K10) -> 0 | M10: =+SUMIFS('Produccion por productor'!H:H,'Produccion por productor'!A:A,RESUMEN!$B$1,'Produccion por productor'!B:B,RESUMEN!$B$2,'Produccion por productor'!C:C,RESUMEN!K10) -> 0 | N10: =+SUMIFS('Produccion por productor'!L:L,'Produccion por productor'!A:A,RESUMEN!$B$1,'Produccion por productor'!B:B,RESUMEN!$B$2,'Produccion por productor'!C:C,RESUMEN!K10)-(SUMIFS('Produccion por productor'!K:K,'Produccion por productor'!A:A,RESUMEN!$B$1,'Produccion por productor'!B:B,RESUMEN!$B$2,'Produccion por productor'!C:C,RESUMEN!K10)) -> 0 | O10: =+((M10+N10)/L10)*100 -> #DIV/0!
A11: DIFERENCIA | H11: =+H7-H9-H10-L6 -> 46 | I11: KG | K11: Agricola Mares | L11: =+SUMIFS('Produccion por productor'!J:J,'Produccion por productor'!A:A,RESUMEN!$B$1,'Produccion por productor'!B:B,RESUMEN!$B$2,'Produccion por productor'!C:C,RESUMEN!K11) -> 80290 | M11: =+SUMIFS('Produccion por productor'!H:H,'Produccion por productor'!A:A,RESUMEN!$B$1,'Produccion por productor'!B:B,RESUMEN!$B$2,'Produccion por productor'!C:C,RESUMEN!K11) -> 64619.1 | N11: =+SUMIFS('Produccion por productor'!L:L,'Produccion por productor'!A:A,RESUMEN!$B$1,'Produccion por productor'!B:B,RESUMEN!$B$2,'Produccion por productor'!C:C,RESUMEN!K11)-(SUMIFS('Produccion por productor'!K:K,'Produccion por productor'!A:A,RESUMEN!$B$1,'Produccion por productor'!B:B,RESUMEN!$B$2,'Produccion por productor'!C:C,RESUMEN!K11)) -> 0 | O11: =+((M11+N11)/L11)*100 -> 80.482127
A12: BINS VOLCADOS | H12: =+SUMIFS('VOLCADO '!H:H,'VOLCADO '!B:B,RESUMEN!B2,'VOLCADO '!C:C,RESUMEN!B1) -> 342 | I12: =+H12*370 -> 126540 | K12: Fruit Crop | L12: =+SUMIFS('Produccion por productor'!J:J,'Produccion por productor'!A:A,RESUMEN!$B$1,'Produccion por productor'!B:B,RESUMEN!$B$2,'Produccion por productor'!C:C,RESUMEN!K12) -> 0 | M12: =+SUMIFS('Produccion por productor'!H:H,'Produccion por productor'!A:A,RESUMEN!$B$1,'Produccion por productor'!B:B,RESUMEN!$B$2,'Produccion por productor'!C:C,RESUMEN!K12) -> 0 | N12: =+SUMIFS('Produccion por productor'!L:L,'Produccion por productor'!A:A,RESUMEN!$B$1,'Produccion por productor'!B:B,RESUMEN!$B$2,'Produccion por productor'!C:C,RESUMEN!K12)-(SUMIFS('Produccion por productor'!K:K,'Produccion por productor'!A:A,RESUMEN!$B$1,'Produccion por productor'!B:B,RESUMEN!$B$2,'Produccion por productor'!C:C,RESUMEN!K12)) -> 0 | O12: =+((M12+N12)/L12)*100 -> #DIV/0!
A13: DESCARTE | H13: =+SUMIFS(DESCARTES!D:D,DESCARTES!A:A,RESUMEN!B1,DESCARTES!B:B,RESUMEN!B2) -> 74 | I13: =+H13*400 -> 29600 | K13: Vision Empresarial del noroeste S.R.L | L13: =+SUMIFS('Produccion por productor'!J:J,'Produccion por productor'!A:A,RESUMEN!B1,'Produccion por productor'!B:B,RESUMEN!B2,'Produccion por productor'!C:C,RESUMEN!K13) -> 21090 | M13: =+SUMIFS('Produccion por productor'!H:H,'Produccion por productor'!A:A,RESUMEN!$B$1,'Produccion por productor'!B:B,RESUMEN!$B$2,'Produccion por productor'!C:C,RESUMEN!K13) -> 14351.4 | N13: =+SUMIFS('Produccion por productor'!L:L,'Produccion por productor'!A:A,RESUMEN!$B$1,'Produccion por productor'!B:B,RESUMEN!$B$2,'Produccion por productor'!C:C,RESUMEN!K13)-(SUMIFS('Produccion por productor'!K:K,'Produccion por productor'!A:A,RESUMEN!$B$1,'Produccion por productor'!B:B,RESUMEN!$B$2,'Produccion por productor'!C:C,RESUMEN!K13)) -> 585 | O13: =+((M13+N13)/L13)*100 -> 70.822191
A14: COMPLETADO | B14: EMBALADORA | C14: CAJONERA
J15: =40*1.085 -> 43.4
I16: =2762/63 -> 43.84127 | O16: =23850/8 -> 2981.25
O17: =+O16*12 -> 35775
K18: =+H12*370 -> 126540
K19: =55*420 -> 23100
K20: =+K18-K19 -> 103440
K21: =+(K20/K18)*100 -> 81.744903

Sheet Cajas
A1: Fecha | B1: Turno | C1: Cajas 18 KG Cajonera | D1: Cajas 18 KG Embaladora | E1: Cajas 15 KG Cajonera | F1: Cajas 15 KG Embaladora | G1: Platto 6 Kg | H1: total | I1: Horas Trabajadas
A2: 46106 | B2: 1 | C2: 1744 | D2: 720 | H2: =+C2+D2+E2+F2+(G2/2) -> 2464 | I2: 0.33333333
A3: 46107 | B3: 1 | C3: 3264 | D3: 2245 | H3: =+C3+D3+E3+F3+(G3/2) -> 5509 | I3: 0.33333333
A4: 46108 | B4: 1 | C4: 4611 | D4: 1609 | H4: =+C4+D4+E4+F4+(G4/2) -> 6220 | I4: 0.5
A5: 46109 | B5: 1 | C5: 1215 | D5: 1062 | E5: 1440 | F5: 160 | H5: =+C5+D5+E5+F5+(G5/2) -> 3877 | I5: 0.33333333
A6: 46111 | B6: 1 | C6: 2304 | D6: 2079 | E6: 1600 | H6: =+C6+D6+E6+F6+(G6/2) -> 5983 | I6: 0.5
A7: 46112 | B7: 1 | C7: 2415 | D7: 1293 | H7: =+C7+D7+E7+F7+(G7/2) -> 3708 | I7: 0.41666667
A8: 46113 | B8: 1 | C8: 3517 | D8: 1946 | H8: =+C8+D8+E8+F8+(G8/2) -> 5463 | I8: 0.5
A9: 46114 | B9: 1 | C9: 1323 | D9: 1674 | H9: =+C9+D9+E9+F9+(G9/2) -> 2997 | I9: 0.33333333
A10: 46116 | B10: 1 | C10: 1044 | D10: 486 | H10: =+C10+D10+E10+F10+(G10/2) -> 1530 | I10: 0.5
A11: 46118 | B11: 1 | C11: 1755 | D11: 846 | H11: =+C11+D11+E11+F11+(G11/2) -> 2601 | I11: 0.5
A12: 46119 | B12: 1 | C12: 1386 | D12: 2016 | H12: =+C12+D12+E12+F12+(G12/2) -> 3402 | I12: 0.3125
A13: 46120 | B13: 1 | C13: 3384 | D13: 1152 | H13: =+C13+D13+E13+F13+(G13/2) -> 4536 | I13: 0.64583333
A14: 46122 | B14: 1 | C14: 3960 | D14: 1080 | H14: =+C14+D14+E14+F14+(G14/2) -> 5040 | I14: 0.39583333
A15: 38818 | B15: 1 | C15: 2808 | D15: 1224 | H15: =+C15+D15+E15+F15+(G15/2) -> 4032 | I15: 0.33333333
A16: 46125 | B16: 1 | C16: 3096 | D16: 1368 | H16: =+C16+D16+E16+F16+(G16/2) -> 4464 | I16: 0.33333333
A17: 46126 | B17: 1 | C17: 4680 | D17: 792 | H17: =+C17+D17+E17+F17+(G17/2) -> 5472 | I17: 0.5
A18: 46127 | B18: 1 | C18: 4923 | D18: 1269 | H18: =+C18+D18+E18+F18+(G18/2) -> 6192 | I18: 0.5
... A20: 46129 | B20: 1 | C20: 4734 | D20: 2304 | H20: =+C20+D20+E20+F20+(G20/2) -> 7038 | I20: 0.5
A21: 46130 | B21: 1 | C21: 4275 | D21: 2610 | E21: 64 | H21: =+C21+D21+E21+F21+(G21/2) -> 6949 | I21: 0.52083333
A22: 46132 | B22: 1 | C22: 4212 | D22: 2403 | E22: 400 | H22: =+C22+D22+E22+F22+(G22/2) -> 7015 | I22: 0.5
A23: 46133 | B23: 1 | C23: 6591 | D23: 4239 | E23: 480 | H23: =+C23+D23+E23+F23+(G23/2) -> 11310 | I23: 0.5
A24: 46134 | B24: 1 | C24: 3942 | D24: 2061 | E24: 400 | H24: =+C24+D24+E24+F24+(G24/2) -> 6403 | I24: 0.5
A25: 46135 | B25: 1 | C25: 4590 | D25: 2358 | H25: =+C25+D25+E25+F25+(G25/2) -> 6948 | I25: 0.5
A26: 46136 | B26: 1 | C26: 3807 | D26: 2439 | E26: 480 | H26: =+C26+D26+E26+F26+(G26/2) -> 6726 | I26: 0.5
A27: 46137 | B27: 2 | C27: 2538 | D27: 2997 | E27: 1440 | H27: =+C27+D27+E27+F27+(G27/2) -> 6975 | I27: 0.45833333
A28: 46139 | B28: 1 | C28: 4959 | D28: 2835 | H28: =+C28+D28+E28+F28+(G28/2) -> 7794 | I28: 0.5
A29: 46140 | B29: 1 | C29: 4203 | D29: 2826 | E29: 720 | H29: =+C29+D29+E29+F29+(G29/2) -> 7749 | I29: 0.5
A30: 46141 | B30: 1 | C30: 3843 | D30: 2682 | E30: 710 | H30: =+C30+D30+E30+F30+(G30/2) -> 7235 | I30: 0.5
A31: 46142 | B31: 1 | C31: 3402 | D31: 2799 | E31: 1550 | H31: =+C31+D31+E31+F31+(G31/2) -> 7751 | I31: 0.5
A32: 46144 | B32: 1 | C32: 1593 | D32: 3600 | E32: 3320 | H32: =+C32+D32+E32+F32+(G32/2) -> 8513 | I32: 0.5625
A33: 46146 | B33: 1 | C33: 3312 | D33: 1647 | H33: =+C33+D33+E33+F33+(G33/2) -> 4959 | I33: 0.33333333
A34: 46146 | B34: 2 | C34: 3240 | D34: 1935 | E34: 480 | H34: =+C34+D34+E34+F34+(G34/2) -> 5655 | I34: 0.33333333
A35: 46147 | B35: 1 | C35: 3886 | D35: 1260 | H35: =+C35+D35+E35+F35+(G35/2) -> 5146
A36: 46147 | B36: 2 | C36: 3033 | D36: 1332 | E36: 560 | H36: =+C36+D36+E36+F36+(G36/2) -> 4925 | I36: 0.33333333
A37: 46148 | B37: 1 | C37: 2772 | D37: 2493 | E37: 880 | H37: =+C37+D37+E37+F37+(G37/2) -> 6145 | I37: 0.29166667
A38: 46179 | B38: 2 | C38: 2853 | D38: 2052 | E38: 1120 | H38: =+C38+D38+E38+F38+(G38/2) -> 6025 | I38: 0.41666667
A39: 46149 | B39: 1 | C39: 2331 | D39: 2520 | E39: 1360 | H39: =+C39+D39+E39+F39+(G39/2) -> 6211 | I39: 10
A40: 46149 | B40: 2 | C40: 1962 | D40: 1746 | E40: 2160 | H40: =+C40+D40+E40+F40+(G40/2) -> 5868 | I40: 0.41666667
A41: 46150 | B41: 1 | C41: 3141 | D41: 1773 | E41: 640 | H41: =+C41+D41+E41+F41+(G41/2) -> 5554 | I41: 0.41666667
...

Sheet DESCARTES
A1: Fecha | B1: Turno | C1: A Mares | D1: Bins | E1: KG | H1: Productor | I1: Kg
A2: 46106 | B2: 1 | C2: A Mares | D2: 24 | E2: =+D2*400 -> 9600 | H2: A Mares | I2: =+SUMIF(C:C,H2:H2,E:E) -> 281200
A3: 46107 | B3: 1 | C3: A Mares | D3: 32 | E3: =+D3*400 -> 12800 | H3: Greyco | I3: =+SUMIF(C:C,H3:H3,E:E) -> 48800
A4: 46108 | B4: 1 | C4: A Mares | D4: 34 | E4: =+D4*400 -> 13600 | H4: Greenpack | I4: =+SUMIF(C:C,H4:H4,E:E) -> 96800
A5: 46108 | B5: 1 | C5: Fruit Crop | D5: 54 | E5: =+D5*400 -> 21600 | H5: Fruit Crop | I5: =+SUMIF(C:C,H5:H5,E:E) -> 263600
A6: 46111 | B6: 1 | C6: A Mares | D6: 49 | E6: =+D6*400 -> 19600 | H6: Vision Empresarial del noroeste S.R.L | I6: =+SUMIF(C:C,H6:H6,E:E) -> 89600
A7: 46111 | B7: 1 | C7: Greyco | D7: 18 | E7: =+D7*400 -> 7200
A8: 46111 | B8: 1 | C8: Greyco | D8: 11 | E8: =+D8*400 -> 4400
A9: 46112 | B9: 1 | C9: A Mares | D9: 14 | E9: =+D9*400 -> 5600
A10: 46113 | B10: 1 | C10: A Mares | D10: 23 | E10: =+D10*400 -> 9200
A11: 46113 | B11: 1 | C11: Greyco | D11: 20 | E11: =+D11*400 -> 8000
A12: 46113 | B12: 1 | C12: Vision Empresarial del noroeste S.R.L | D12: 5 | E12: =+D12*400 -> 2000 | H12: 409
A13: 46114 | B13: 1 | C13: Vision Empresarial del noroeste S.R.L | D13: 30 | E13: =+D13*400 -> 12000 | H13: 83 | J13: =83/409 -> 0.20293399
A14: 46114 | B14: 1 | C14: Greyco | D14: 6 | E14: =+D14*400 -> 2400 | H14: =+(H13/H12)*100 -> 20.293399
A15: 46116 | B15: 1 | C15: Vision Empresarial del noroeste S.R.L | D15: 39 | E15: =+D15*400 -> 15600
A16: 46116 | B16: 1 | C16: Fruit Crop | D16: 10 | E16: =+D16*400 -> 4000
A17: 46118 | B17: 1 | C17: Fruit Crop | D17: 8 | E17: =+D17*400 -> 3200
A18: 46118 | B18: 1 | C18: A Mares | D18: 18 | E18: =+D18*400 -> 7200
A19: 46118 | B19: 1 | C19: Vision Empresarial del noroeste S.R.L | D19: 33 | E19: =+D19*400 -> 13200
A20: 46119 | B20: 1 | C20: A Mares | D20: 34 | E20: =+D20*400 -> 13600
A21: 46119 | B21: 1 | C21: Greyco | D21: 6 | E21: =+D21*400 -> 2400
A22: 46119 | B22: 1 | C22: Greenpack | D22: 4 | E22: =+D22*400 -> 1600
A23: 46119 | B23: 1 | C23: Vision Empresarial del noroeste S.R.L | D23: 6 | E23: =+D23*400 -> 2400
A24: 46120 | B24: 1 | C24: Fruit Crop | D24: 27 | E24: =+D24*400 -> 10800
A25: 46122 | B25: 1 | C25: Fruit Crop | D25: 36 | E25: =+D25*400 -> 14400
A26: 46123 | B26: 1 | C26: Fruit Crop | D26: 3 | E26: =+D26*400 -> 1200
... A110: 46151 | B110: 2 | C110: Greyco | D110: 5 | E110: =+D110*400 -> 2000
E111: =+D111*400 -> 0
E112: =+D112*400 -> 0
E113: =+D113*400 -> 0
E114: =+D114*400 -> 0
E115: =+D115*400 -> 0
E116: =+D116*400 -> 0
E117: =+D117*400 -> 0
E118: =+D118*400 -> 0
E119: =+D119*400 -> 0
E120: =+D120*400 -> 0
E121: =+D121*400 -> 0
E122: =+D122*400 -> 0
... E665: =+D665*400 -> 0

Sheet Pisos
A1: Fecha | B1: Productor | C1: Finca | D1: UP | E1: Cajas 15 KG | F1: CAJAS 18 KG | G1: Turno | H1: KG | I1: Total Cajas | M1: 1
A2: 46105 | B2: Agricola Mares | C2: Claudia | D2: 0290-003 | E2: 1 | H2: =+E2*15+F2*18 -> 15 | I2: =+F2+E2 -> 1 | M2: 2
A3: 46106 | B3: Agricola Mares | C3: Claudia | D3: 0290-003 | E3: 8 | F3: 92 | G3: 1 | H3: =+E3*15+F3*18 -> 1776 | I3: =+F3+E3 -> 100
A4: 46107 | B4: Agricola Mares | C4: Claudia | D4: 0290-003 | E4: 33 | F4: 56 | G4: 1 | H4: =+E4*15+F4*18 -> 1503 | I4: =+F4+E4 -> 89
A5: 46108 | B5: Agricola Mares | C5: Claudia | D5: 0290-003 | F5: 79 | G5: 1 | H5: =+E5*15+F5*18 -> 1422 | I5: =+F5+E5 -> 79
A6: 46108 | B6: Vision Empresarial del noroeste S.R.L | C6: Antamapu | D6: 0136-001 | F6: 19 | G6: 1 | H6: =+E6*15+F6*18 -> 342 | I6: =+F6+E6 -> 19
A7: 46110 | B7: Vision Empresarial del noroeste S.R.L | C7: Antamapu | D7: 0136-001 | E7: 22 | F7: 12 | H7: =+E7*15+F7*18 -> 546 | I7: =+F7+E7 -> 34
A8: 46110 | B8: Agricola Mares SA | C8: Claudia | D8: 0290-003 | F8: 9 | H8: =+E8*15+F8*18 -> 162 | I8: =+F8+E8 -> 9
A9: 46110 | B9: Greyco SRL | C9: El Molino | D9: 0419-006 | F9: 57 | H9: =+E9*15+F9*18 -> 1026 | I9: =+F9+E9 -> 57
A10: 46111 | B10: Greyco SRL | C10: El Molino | D10: 0419-006 | F10: 44 | H10: =+E10*15+F10*18 -> 792 | I10: =+F10+E10 -> 44
A11: 46111 | B11: Agricola Mares SA | C11: Claudia | D11: 0290-003 | F11: 18 | H11: =+E11*15+F11*18 -> 324 | I11: =+F11+E11 -> 18
A12: 46112 | B12: Agricola Mares SA | C12: Claudia | D12: 0290-003 | F12: 64 | H12: =+E12*15+F12*18 -> 1152 | I12: =+F12+E12 -> 64
A13: 46113 | B13: Agricola Mares SA | C13: Claudia | D13: 0290-003 | F13: 18 | H13: =+E13*15+F13*18 -> 324 | I13: =+F13+E13 -> 18
A14: 46113 | B14: Vision Empresarial del noroeste S.R.L | C14: Antamapu | D14: 0136-001 | F14: 40 | H14: =+E14*15+F14*18 -> 720 | I14: =+F14+E14 -> 40
A15: 46114 | B15: Vision Empresarial del noroeste S.R.L | C15: Antamapu | D15: 0136-001 | F15: =134+14 -> 148 | H15: =+E15*15+F15*18 -> 2664 | I15: =+F15+E15 -> 148
A16: 46116 | B16: Fruit Crop | C16: Yaquilo | D16: 0793-001 | F16: 85 | H16: =+E16*15+F16*18 -> 1530 | I16: =+F16+E16 -> 85
A17: 46118 | B17: Greenpack | C17: Claudia | D17: 0290-003 | F17: 64 | G17: 1 | H17: =+E17*15+F17*18 -> 1152 | I17: =+F17+E17 -> 64
A18: 46118 | B18: Vision Empresarial del noroeste S.R.L | C18: Antamapu | D18: 0136-001 | F18: 12 | G18: 1 | H18: =+E18*15+F18*18 -> 216 | I18: =+F18+E18 -> 12
A19: 46119 | B19: Greenpack | C19: Tajamar | D19: 0669-001 | F19: 6 | G19: 1 | H19: =+E19*15+F19*18 -> 108 | I19: =+F19+E19 -> 6
A20: 46119 | B20: Agricola Mares SA | C20: Claudia | D20: 0290-003 | F20: 1 | G20: 1 | H20: =+E20*15+F20*18 -> 18 | I20: =+F20+E20 -> 1
A21: 46119 | B21: Greyco | C21: La Luz | D21: 0268-001 | F21: 3 | G21: 1 | H21: =+E21*15+F21*18 -> 54 | I21: =+F21+E21 -> 3
A22: 46120 | B22: Fruit Crop | C22: Yaquilo | D22: 0793-004 | F22: 63 | G22: 1 | H22: =+E22*15+F22*18 -> 1134 | I22: =+F22+E22 -> 63
A23: 46122 | B23: Fruit Crop | C23: Yaquilo | D23: 0793-003 | F23: 115 | G23: 1 | H23: =+E23*15+F23*18 -> 2070 | I23: =+F23+E23 -> 115
A24: 46123 | B24: GREYCO | C24: La Luz | D24: 0268-001 | F24: 100 | G24: 1 | H24: =+E24*15+F24*18 -> 1800 | I24: =+F24+E24 -> 100
A25: 46125 | B25: GREYCO | C25: La Luz | D25: 0268-001 | F25: 103 | G25: 1 | H25: =+E25*15+F25*18 -> 1854 | I25: =+F25+E25 -> 103
A26: 46125 | B26: Greenpack | C26: Tajamar | D26: 0669-001 | F26: 5 | G26: 1 | H26: =+E26*15+F26*18 -> 90 | I26: =+F26+E26 -> 5
A27: 46125 | B27: Vision Empresarial del noroeste S.R.L | C27: Antamapu | D27: 0136-001 | F27: 5 | G27: 1 | H27: =+E27*15+F27*18 -> 90 | I27: =+F27+E27 -> 5
A28: 46126 | B28: Vision Empresarial del noroeste S.R.L | C28: Antamapu | D28: 0136-001 | F28: 5 | G28: 1 | H28: =+E28*15+F28*18 -> 90 | I28: =+F28+E28 -> 5
... A33: 46127 | B33: Fruit Crop | C33: Yaquilo | D33: 0793-001 | F33: 55 | G33: 1 | H33: =+E33*15+F33*18 -> 990 | I33: =+F33+E33 -> 55
A34: 46128 | B34: Fruit Crop | D34: 0541-001 | F34: 21 | G34: 1 | H34: =+E34*15+F34*18 -> 378 | I34: =+F34+E34 -> 21
A35: 46128 | B35: Agricola Mares SA | C35: Claudia | D35: 0290-003 | F35: 5 | G35: 1 | H35: =+E35*15+F35*18 -> 90 | I35: =+F35+E35 -> 5
A36: 46129 | B36: Greenpack | C36: Tajamar | D36: 0669-001/008 | F36: 69 | G36: 1 | H36: =+E36*15+F36*18 -> 1242 | I36: =+F36+E36 -> 69
A37: 46129 | B37: Fruit Crop | C37: Yaquilo | D37: 0793-001 | F37: 83 | G37: 1 | H37: =+E37*15+F37*18 -> 1494 | I37: =+F37+E37 -> 83
A38: 46129 | B38: Vision Empresarial del noroeste S.R.L | C38: Antamapu | D38: 0136-014 | F38: 18 | G38: 1 | H38: =+E38*15+F38*18 -> 324 | I38: =+F38+E38 -> 18
A39: 46130 | B39: Fruit Crop | C39: Yaquilo | D39: 0793-001 | F39: 115 | G39: 1 | H39: =+E39*15+F39*18 -> 2070 | I39: =+F39+E39 -> 115
A40: 46130 | B40: Greenpack | C40: Tajamar | D40: 0669-001 | E40: 64 | F40: 93 | G40: 1 | H40: =+E40*15+F40*18 -> 2634 | I40: =+F40+E40 -> 157
A41: 46132 | B41: Agricola Mares SA | C41: Claudia | D41: 0290-003 | F41: 60 | G41: 1 | H41: =+E41*15+F41*18 -> 1080 | I41: =+F41+E41 -> 60
A42: 46132 | B42: Greenpack | C42: Tajamar | D42: 0669-001 | E42: 72 | G42: 1 | H42: =+E42*15+F42*18 -> 1080 | I42: =+F42+E42 -> 72
A43: 46132 | B43: Fruit Crop | D43: 0541-001 | F43: 27 | G43: 1 | H43: =+E43*15+F43*18 -> 486 | I43: =+F43+E43 -> 27
A44: 46133 | B44: Agricola Mares SA | C44: Claudia | D44: 0290-003 | E44: 59 | F44: 101 | G44: 1 | H44: =+E44*15+F44*18 -> 2703 | I44: =+F44+E44 -> 160
...

Sheet Produccion por productor
A1: Fecha | B1: Turno | C1: Productor | D1: Up | E1: Finca | F1: Produccion sistema | H1: KG Empaque | I1: KG PISO | J1: Volcado | K1: Piso inicial | L1: Piso Final | M1: Rendimiento Empaque | N1: Rendimiento Comercial
A2: 46106 | B2: 1 | C2: Agricola Mares | D2: 290-003 | E2: Claudia | F2: 48975 | G2: =+F2+I2 -> 48975 | H2: =+(F2*0.05)+F2 -> 51423.75 | J2: 60310 | M2: =+((H2/J2)+I2)*100 -> 85.26571 | N2: =+((F2+I2)/J2)*100 -> 81.205439
A3: 46107 | B3: 1 | C3: Agricola Mares | D3: 290-003 | E3: Claudia | F3: 75945 | G3: =+F3+I3 -> 75945 | H3: =+(F3*0.05)+F3 -> 79742.25 | J3: 97680 | M3: =+((H3+I3)/J3)*100 -> 81.63621 | N3: =+((F3+I3)/J3)*100 -> 77.748771
A4: 46108 | B4: 1 | C4: Agricola Mares | D4: 290-003 | E4: Claudia | F4: 37041 | G4: =+F4+I4 -> 37041 | H4: =+(F4*0.05)+F4 -> 38893.05 | J4: 56610 | M4: =+((H4+I4)/J4)*100 -> 68.703498 | N4: =+((F4+I4)/J4)*100 -> 65.431902
A5: 46108 | B5: 1 | C5: Greyco | D5: 268-001 | E5: El Molino | F5: =18897+1026 -> 19923 | G5: =+F5+I5 -> 20949 | H5: =+(F5*0.05)+F5 -> 20919.15 | I5: 1026 | J5: 35890 | M5: =+((H5+I5)/J5)*100 -> 61.145584 | N5: =+((F5+I5)/J5)*100 -> 58.37002
A6: 46108 | B6: 1 | C6: Vision Empresarial del noroeste S.R.L | D6: 136-001 | E6: Antamapu | F6: 44226 | G6: =+F6+I6 -> 44226 | H6: =+(F6*0.05)+F6 -> 46437.3 | I6: =+L6-K6 -> 0 | J6: 59200 | M6: =+((H6+I6)/J6)*100 -> 78.441385 | N6: =+((F6+I6)/J6)*100 -> 74.706081
A7: 46109 | B7: 1 | C7: Agricola Mares | D7: 290-003 | E7: Claudia | F7: 50643 | G7: =+F7+I7 -> 50805 | H7: =+(F7*0.05)+F7 -> 53175.15 | I7: 162 | J7: 79550 | M7: =+((H7+I7)/J7)*100 -> 67.048586 | N7: =+((F7+I7)/J7)*100 -> 63.865493
A8: 46109 | B8: 1 | C8: Vision Empresarial del noroeste S.R.L | D8: 136-001 | E8: Antamapu | F8: 9645 | G8: =+F8+I8 -> 10191 | H8: =+(F8*0.05)+F8 -> 10127.25 | I8: 546 | J8: 14060 | M8: =+((H8+I8)/J8)*100 -> 75.912162 | N8: =+((F8+I8)/J8)*100 -> 72.482219
A9: 46109 | B9: 1 | C9: Greyco | D9: 268-001 | E9: El Molino | F9: 5607 | G9: =+F9+I9 -> 5607 | H9: =+(F9*0.05)+F9 -> 5887.35 | J9: 6290 | M9: =+((H9+I9)/J9)*100 -> 93.598569 | N9: =+((F9+I9)/J9)*100 -> 89.141494
A10: 46111 | B10: 1 | C10: Agricola Mares | D10: 290-003 | E10: Claudia | F10: 81339 | G10: =+F10+I10 -> 81663 | H10: =+(F10*0.05)+F10 -> 85405.95 | I10: 324 | J10: 112210 | M10: =+((H10+I10)/J10)*100 -> 76.401346 | N10: =+((F10+I10)/J10)*100 -> 72.776936 | O10: 669
A11: 46111 | B11: 1 | C11: Greyco | D11: 0268-/419 | F11: 18306 | G11: =+F11+I11 -> 19098 | H11: =+(F11*0.05)+F11 -> 19221.3 | I11: 792 | J11: 34410 | M11: =+((H11+I11)/J11)*100 -> 58.16129 | N11: =+((F11+I11)/J11)*100 -> 55.501308 | O11: 419
A12: 46112 | B12: 1 | C12: Agricola Mares | D12: 290-003 | E12: Claudia | F12: 62136 | G12: =+F12+I12 -> 62964 | H12: =+(F12*0.05)+F12 -> 65242.8 | I12: =+L12-K12 -> 828 | J12: 82510 | K12: 324 | L12: 1152 | M12: =+((H12+I12)/J12)*100 -> 80.076112 | N12: =+((F12+I12)/J12)*100 -> 76.31075
A13: 46113 | B13: 1 | C13: Greyco | D13: 0268-/419 | F13: 5004 | G13: =+F13+I13 -> 5004 | H13: =+(F13*0.05)+F13 -> 5254.2 | I13: 0 | J13: 18500 | M13: =+((H13+I13)/J13)*100 -> 28.401081 | N13: =+((F13+I13)/J13)*100 -> 27.048649
A14: 46113 | B14: 1 | C14: Vision Empresarial del noroeste S.R.L | F14: 2952 | G14: =+F14+I14 -> 3672 | H14: =+(F14*0.05)+F14 -> 3099.6 | I14: =+L14-K14 -> 720 | J14: 10730 | L14: 720 | M14: =+((H14+I14)/J14)*100 -> 35.59739 | N14: =+((F14+I14)/J14)*100 -> 34.221808
A15: 46113 | B15: 1 | C15: Agricola Mares | D15: 290-003 | E15: Claudia | F15: 85580 | G15: =+F15+I15 -> 84428 | H15: =+(F15*0.05)+F15 -> 89859 | I15: =+L15-K15 -> -1152 | J15: 102860 | K15: 1152 | M15: =+((H15+I15)/J15)*100 -> 86.240521 | N15: =+((F15+I15)/J15)*100 -> 82.080498
A16: 46114 | B16: 1 | C16: Vision Empresarial del noroeste S.R.L | D16: 136-001 | E16: Antamapu | F16: 51156 | G16: =+F16+I16 -> 52758 | H16: =+(F16*0.05)+F16 -> 53713.8 | I16: =+L16-K16 -> 1602 | J16: 72150 | K16: 720 | L16: 2322 | M16: =+((H16+I16)/J16)*100 -> 76.667775 | N16: =+((F16+I16)/J16)*100 -> 73.122661
A17: 46114 | B17: 1 | C17: Greyco | D17: 268-001 | E17: La Luz | F17: 1206 | G17: =+F17+I17 -> 1206 | H17: =+(F17*0.05)+F17 -> 1266.3 | I17: =+L17-K17 -> 0 | J17: 2590 | M17: =+((H17+I17)/J17)*100 -> 48.891892 | N17: =+((F17+I17)/J17)*100 -> 46.563707
A18: 46116 | B18: 1 | C18: Vision Empresarial del noroeste S.R.L | D18: 136-001 | E18: Antamapu | F18: 57528 | G18: =+F18+I18 -> 54864 | H18: =+(F18*0.05)+F18 -> 60404.4 | I18: =+L18-K18 -> -2664 | J18: 83990 | K18: 2664 | M18: =+((H18+I18)/J18)*100 -> 68.746756 | N18: =+((F18+I18)/J18)*100 -> 65.322062
A19: 46116 | B19: 1 | C19: fruit crop sa | D19: 793-001 | E19: Yaquilo | F19: 30978 | G19: =+F19+I19 -> 32508 | H19: =+(F19*0.05)+F19 -> 32526.9 | I19: =+L19-K19 -> 1530 | J19: 42920 | L19: 1530 | M19: =+((H19+I19)/J19)*100 -> 79.34972 | N19: =+((F19+I19)/J19)*100 -> 75.740913
A20: 46118 | B20: 1 | C20: Fruit Crop | D20: 0793-001 | E20: Yaquilo | F20: 19350 | G20: =+F20+I20 -> 17820 | H20: =+(F20*0.05)+F20 -> 20317.5 | I20: =+L20-K20 -> -1530 | J20: 21830 | K20: 1530 | M20: =+((H20+I20)/J20)*100 -> 86.062758 | N20: =+((F20+I20)/J20)*100 -> 81.630783
A21: 46118 | B21: 1 | C21: Agricola Mares | D21: 0290-003 | E21: Claudia | F21: 14778 | G21: =+F21+I21 -> 15930 | H21: =+(F21*0.05)+F21 -> 15516.9 | I21: =+L21-K21 -> 1152 | J21: 25530 | L21: 1152 | M21: =+((H21+I21)/J21)*100 -> 65.291422 | N21: =+((F21+I21)/J21)*100 -> 62.39718
A22: 46118 | B22: 1 | C22: Vision Empresarial del noroeste S.R.L | D22: 0136-001 | E22: Antamapu | F22: 44586 | G22: =+F22+I22 -> 44802 | H22: =+(F22*0.05)+F22 -> 46815.3 | I22: =+L22-K22 -> 216 | J22: 65120 | L22: 216 | M22: =+((H22+I22)/J22)*100 -> 72.222512 | N22: =+((F22+I22)/J22)*100 -> 68.79914
A23: 46119 | B23: 1 | C23: Agricola Mares | D23: 0290-003 | E23: Claudia | F23: 25722 | G23: =+F23+I23 -> 24588 | H23: =+(F23*0.05)+F23 -> 27008.1 | I23: =+L23-K23 -> -1134 | J23: 38110 | K23: 1152 | L23: 18 | M23: =+((H23+I23)/J23)*100 -> 67.893204 | N23: =+((F23+I23)/J23)*100 -> 64.518499
A24: 46119 | B24: 1 | C24: Greyco | D24: 0268-001 | E24: La Luz | F24: 12708 | G24: =+F24+I24 -> 12762 | H24: =+(F24*0.05)+F24 -> 13343.4 | I24: =+L24-K24 -> 54 | J24: 17020 | L24: 54 | M24: =+((H24+I24)/J24)*100 -> 78.715629 | N24: =+((F24+I24)/J24)*100 -> 74.982374
A25: 46119 | B25: 1 | C25: Greenpack | D25: 0669-001 | E25: Tajamar | F25: 9450 | G25: =+F25+I25 -> 9558 | H25: =+(F25*0.05)+F25 -> 9922.5 | I25: =+L25-K25 -> 108 | J25: 13690 | L25: 108 | M25: =+((H25+I25)/J25)*100 -> 73.268809 | N25: =+((F25+I25)/J25)*100 -> 69.817385
A26: 46119 | B26: 1 | C26: Vision Empresarial del noroeste S.R.L | D26: 0136-001 | E26: Antamapu | F26: 11178 | G26: =+F26+I26 -> 10962 | H26: =+(F26*0.05)+F26 -> 11736.9 | I26: =+L26-K26 -> -216 | J26: 18130 | K26: 216 | M26: =+((H26+I26)/J26)*100 -> 63.546056 | N26: =+((F26+I26)/J26)*100 -> 60.46332
A27: 46120 | B27: 1 | C27: Fruit Crop | D27: 0793-001/002/003/004 | E27: Yaquilo | F27: 81648 | G27: =+F27+I27 -> 81648 | H27: =+(F27*0.05)+F27 -> 85730.4 | I27: =+L27-K27 -> 0 | J27: 103230 | M27: =+((H27+I27)/J27)*100 -> 83.047951 | N27: =+((F27+I27)/J27)*100 -> 79.093287
A28: 46122 | B28: 1 | C28: Fruit Crop | D28: 0793-004/002/003/001 | E28: Yaquilo | F28: 89730 | G28: =+F28+I28 -> 90666 | H28: =+(F28*0.05)+F28 -> 94216.5 | I28: =+L28-K28 -> 936 | J28: 117290 | K28: 1134 | L28: 2070 | M28: =+((H28+I28)/J28)*100 -> 81.125842 | N28: =+((F28+I28)/J28)*100 -> 77.300708
A29: 46123 | B29: 1 | C29: Fruit Crop | D29: 0739-001/002/003 | E29: Yaquilo | F29: 8658 | G29: =+F29+I29 -> 6588 | H29: =+(F29*0.05)+F29 -> 9090.9 | I29: =+L29-K29 -> -2070 | J29: 10730 | K29: 2070 | M29: =+((H29+I29)/J29)*100 -> 65.432432 | N29: =+((F29+I29)/J29)*100 -> 61.39795
A30: 46123 | B30: 1 | C30: Agricola Mares | D30: 0290-008/003 | E30: Claudia | F30: 28620 | G30: =+F30+I30 -> 28620 | H30: =+(F30*0.05)+F30 -> 30051 | I30: =+L30-K30 -> 0 | J30: 37370 | M30: =+((H30+I30)/J30)*100 -> 80.414771 | N30: =+((F30+I30)/J30)*100 -> 76.585496
A31: 46123 | B31: 1 | C31: Greenpack | D31: 0669-001/003 | E31: Tajamar | F31: 26388 | G31: =+F31+I31 -> 26388 | H31: =+(F31*0.05)+F31 -> 27707.4 | I31: =+L31-K31 -> 0 | J31: 35500 | M31: =+((H31+I31)/J31)*100 -> 78.049014 | N31: =+((F31+I31)/J31)*100 -> 74.332394
A32: 46123 | B32: 1 | C32: Greyco | D32: 0268-001 | E32: La Luz | F32: 6678 | G32: =+F32+I32 -> 8262 | H32: =+(F32*0.05)+F32 -> 7011.9 | I32: =+L32-K32 -> 1584 | J32: 11100 | L32: 1584 | M32: =+((H32+I32)/J32)*100 -> 77.440541 | N32: =+((F32+I32)/J32)*100 -> 74.432432
A33: 46123 | B33: 1 | C33: Vision Empresarial del noroeste S.R.L | D33: 0136-001 | E33: Antamapu | G33: =+F33+I33 -> 216 | H33: =+(F33*0.05)+F33 -> 0 | I33: =+L33-K33 -> 216 | J33: 740 | L33: 216 | M33: =+((H33+I33)/J33)*100 -> 29.189189 | N33: =+((F33+I33)/J33)*100 -> 29.189189
A34: 46125 | B34: 1 | C34: Fruit Crop | D34: 0793-002/005/004/006/003/007/008 | E34: Yaquilo | F34: 61110 | G34: =+F34+I34 -> 59310 | H34: =+(F34*0.05)+F34 -> 64165.5 | I34: =+L34-K34 -> -1800 | J34: 72890 | K34: 1800 | M34: =+((H34+I34)/J34)*100 -> 85.561119 | N34: =+((F34+I34)/J34)*100 -> 81.369186
A35: 46125 | B35: 1 | C35: Agricola Mares | D35: 0290-003 | E35: Claudia | F35: 720 | G35: =+F35+I35 -> 720 | H35: =+(F35*0.05)+F35 -> 756 | I35: =+L35-K35 -> 0 | J35: 1110 | M35: =+((H35+I35)/J35)*100 -> 68.108108 | N35: =+((F35+I35)/J35)*100 -> 64.864865
A36: 46125 | B36: 1 | C36: Vision Empresarial del noroeste S.R.L | D36: 0136-001 | E36: Antamapu | F36: 15426 | G36: =+F36+I36 -> 15516 | H36: =+(F36*0.05)+F36 -> 16197.3 | I36: =+L36-K36 -> 90 | J36: 17760 | L36: 90 | M36: =+((H36+I36)/J36)*100 -> 91.70777 | N36: =+((F36+I36)/J36)*100 -> 87.364865
A37: 46125 | B37: 1 | C37: Greenpack | D37: 0669-001 | E37: Tajamar | F37: 126 | G37: =+F37+I37 -> 216 | H37: =+(F37*0.05)+F37 -> 132.3 | I37: =+L37-K37 -> 90 | J37: 370 | L37: 90 | M37: =+((H37+I37)/J37)*100 -> 60.081081 | N37: =+((F37+I37)/J37)*100 -> 58.378378
A38: 46125 | B38: 1 | C38: Greyco | D38: 0268-001 | E38: La Luz | F38: 2196 | G38: =+F38+I38 -> 4050 | H38: =+(F38*0.05)+F38 -> 2305.8 | I38: =+L38-K38 -> 1854 | J38: 6290 | L38: 1854 | M38: =+((H38+I38)/J38)*100 -> 66.133545 | N38: =+((F38+I38)/J38)*100 -> 64.387917
A39: 46126 | B39: 1 | C39: Fruit Crop | D39: 0793-002/004/007 | E39: Yaquilo | F39: 41238 | G39: =+F39+I39 -> 41238 | H39: =+(F39*0.05)+F39 -> 43299.9 | I39: =+L39-K39 -> 0 | J39: 49580 | M39: =+((H39+I39)/J39)*100 -> 87.333401 | N39: =+((F39+I39)/J39)*100 -> 83.174667
A40: 46126 | B40: 1 | C40: Agricola Mares | D40: 0290-003 | E40: Claudia | F40: 52848 | G40: =+F40+I40 -> 52848 | H40: =+(F40*0.05)+F40 -> 55490.4 | I40: =+L40-K40 -> 0 | J40: 60680 | M40: =+((H40+I40)/J40)*100 -> 91.447594 | N40: =+((F40+I40)/J40)*100 -> 87.092947
...
